
MONGO ERROR WHEN WE CAN'T CONNECT TO MONGO.

{"result": false, "traceback": ["Traceback (most recent call last):
  File \"./wsgi.py\", line 58, in fetch
    record = mrp.do_fetch(module=fields['module'][0], table=fields['table'][0], primarykey=fields['key'])
  File \"./wsgi.py\", line 36, in do_fetch
    table_def = self.get_table_definition(module, table)
  File \"./wsgi.py\", line 30, in get_table_definition
    return collection.find_one({\"module\": module, \"table\": table})
  File \"/home/susmapi/.venv/lib/python3.5/site-packages/pymongo/collection.py\", line 1225, in find_one
    for result in cursor.limit(-1):
  File \"/home/susmapi/.venv/lib/python3.5/site-packages/pymongo/cursor.py\", line 1169, in next
    if len(self.__data) or self._refresh():
  File \"/home/susmapi/.venv/lib/python3.5/site-packages/pymongo/cursor.py\", line 1068, in _refresh
    self.__session = self.__collection.database.client._ensure_session()
  File \"/home/susmapi/.venv/lib/python3.5/site-packages/pymongo/mongo_client.py\", line 1394, in _ensure_session
    return self.start_session(causal_consistency=False)
  File \"/home/susmapi/.venv/lib/python3.5/site-packages/pymongo/mongo_client.py\", line 1372, in start_session
    server_session = self._get_server_session()
  File \"/home/susmapi/.venv/lib/python3.5/site-packages/pymongo/mongo_client.py\", line 1380, in _get_server_session
    return self._topology.get_server_session()
  File \"/home/susmapi/.venv/lib/python3.5/site-packages/pymongo/topology.py\", line 432, in get_server_session
    None)
  File \"/home/susmapi/.venv/lib/python3.5/site-packages/pymongo/topology.py\", line 199, in _select_servers_loop
    self._error_message(selector))
pymongo.errors.ServerSelectionTimeoutError: connection closed,connection closed,connection closed
"], "message": "Object not found (<class 'pymongo.errors.ServerSelectionTimeoutError'>: connection closed,connection closed,connection closed)"}

